<?xml version="1.0" encoding="utf-8"?>
<mujoco>
    <compiler angle="radian" coordinate="local" meshdir="fetch" texturedir="texture"></compiler>
	<size nconmax="2000" njmax="500"/>
	<option timestep="0.002">
		<flag warmstart="enable"></flag>
	</option>
    <include file="shared.xml"></include>
    <worldbody>
        <geom name="floorgeom0" pos="1.2 -4.00 0" size="1.0 8.0 1" type="plane" condim="3" material="floor_mat"></geom>
		<body name="floor0" pos="1.45 -0.20 1.03">
			<!-- <site name="target01" pos="0 0.15 0" size="0.04" rgba="0.3 0 0 0" type="sphere"></site>
      <site name="target02" pos="0 0.45 0" size="0.04" rgba="0.3 0 0 0" type="sphere"></site>
      <site name="target0" pos="0 0.8 -0.30" size="0.01 0.01 0.01" type="box" rgba="0.3 0 0 0"></site> -->
		</body>
		<body pos="0.75 0 0.71" name="pedestal0">
			<geom name="pedestalgeom0" size="0.4 0.4 0.02" type="box" mass="2000" material="pedestal_mat"></geom>
			<site pos="0.30 0.30 0" size="0.075 0.075 0.002" type="box" name="robotmountsite0" rgba="0.55 0.54 0.53 0" />
		</body>
    <include file="robot_xarm.xml"></include>
    <body pos="1.555 0.3 0.53625" name="table0">
			<site name="t1" type="box" pos="0 0 0" size="0.002 0.002 0.002" rgba="1 0 0 0"/>
		</body>
       
        <body name="drawer_box" pos="1.45 -0.20 0.35" quat="0.7071 0 0 0.7071">
        <joint name="drawer_box:joint" type = "free" limited="false"></joint>
          <geom name="bottom_wall" type="box" pos="0 0 0" size="0.15 0.225 0.02" rgba="1 1 1 1" solimp="0.99 0.99 0.01" conaffinity="4" mass="1000" solref="0.01 1"/>
          <geom name="top_wall" type="box" pos="0 0 0.7" size="0.15 0.225 0.001" rgba="1 1 1 1" solimp="0.99 0.99 0.01" conaffinity="4" mass="1000" solref="0.01 1"/>
          <geom name="left_wall" type="box" pos="0 -0.225 0.35" size="0.15 0.001 0.35" rgba="1 1 1 1" solimp="0.99 0.99 0.01" conaffinity="4" mass="1000" solref="0.01 1"/>
          <geom name="right_wall" type="box" pos="0 0.225 0.35" size="0.15 0.001 0.35" rgba="1 1 1 1" solimp="0.99 0.99 0.01" conaffinity="4" mass="1000" solref="0.01 1"/>
          <geom name="back_wall" type="box" pos="-0.15 0 0.35" size="0.001 0.225 0.35" rgba="1 1 1 1" solimp="0.99 0.99 0.01" conaffinity="4" mass="1000" solref="0.01 1"/>
          
          
          <body name="drawer1" pos="0 0 0.48">
            <geom name="bottom" type="box" pos="0 0 0" size="0.15 0.2 0.001" rgba="0.615 0.71 0.576 1" solimp="0.99 0.99 0.01" conaffinity="4" mass="0.1" solref="0.01 1"/>
            <geom name="left" type="box" pos="0 -0.2 0.1" size="0.15 0.001 0.1" rgba="0.615 0.71 0.576 1" solimp="0.99 0.99 0.01" conaffinity="4" mass="0.1" solref="0.01 1"/>
            <geom name="right" type="box" pos="0 0.2 0.1" size="0.15 0.001 0.1" rgba="0.615 0.71 0.576 1" solimp="0.99 0.99 0.01" conaffinity="4" mass="0.1" solref="0.01 1"/>
            <geom name="front" type="box" pos="0.15 0 0.1" size="0.001 0.2 0.1" rgba="0.615 0.71 0.576 1" solimp="0.99 0.99 0.01" conaffinity="4" mass="0.1" solref="0.01 1"/>
            <geom name="back" type="box" pos="-0.15 0 0.1" size="0.001 0.2 0.1" rgba="0.615 0.71 0.576 1" solimp="0.99 0.99 0.01" conaffinity="4" mass="0.1" solref="0.01 1"/>
            <geom name="handle_11" type="capsule" fromto="0.15 -0.1 0.1 0.2 -0.05 0.1" size="0.01" rgba="1 1 1 1" solimp="0.99 0.99 0.01" conaffinity="4" mass="0.05" solref="0.01 1"/>
            <geom name="handle_12" type="capsule" fromto="0.2 -0.05 0.1 0.2 0.05 0.1" size="0.01" rgba="1 1 1 1" solimp="0.99 0.99 0.01" conaffinity="4" mass="0.05" solref="0.01 1"/>
            <geom name="handle_13" type="capsule" fromto="0.2 0.05 0.1 0.15 0.1 0.1" size="0.01" rgba="1 1 1 1" solimp="0.99 0.99 0.01" conaffinity="4" mass="0.05" solref="0.01 1"/>
            <site name="handle" type="sphere" pos="0.2 0 0.105" size="0.02" rgba="1 0 0 0"/>
            <site name="handle_up" type="sphere" pos="0.2 0 0.115" size="0.02" rgba="1 0 0 0"/>
            <site name="target01" pos="0 0.15 0.2" size="0.04" rgba="0.3 0 0 0" type="sphere"></site>
            <site name="target02" pos="0 0.45 0.2" size="0.04" rgba="0.3 0 0 0" type="sphere"></site>
            <site name="target0" pos="0 0.8 0.0" size="0.01 0.01 0.01" type="box" rgba="0.3 0 0 0"></site>
            <joint type="slide" pos="0 0 0" name="drawer1_joint" damping="0.5" axis="1 0 0" frictionloss="1000" limited="true" range="-0.05 0.4"/>
          </body>
          
          <body name="drawer2" pos="0 0 0.24">
            <geom name="bottom2" type="box" pos="0 0 0" size="0.15 0.2 0.001" rgba="0.615 0.71 0.576 1" solimp="0.99 0.99 0.01" contype="1" conaffinity="1" mass="100" solref="0.01 1"/>
            <geom name="left2" type="box" pos="0 -0.2 0.1" size="0.15 0.001 0.1" rgba="0.615 0.71 0.576 1" solimp="0.99 0.99 0.01" contype="1" conaffinity="1" mass="100" solref="0.01 1"/>
            <geom name="right2" type="box" pos="0 0.2 0.1" size="0.15 0.001 0.1" rgba="0.615 0.71 0.576 1" solimp="0.99 0.99 0.01" contype="1" conaffinity="1" mass="100" solref="0.01 1"/>
            <geom name="front2" type="box" pos="0.15 0 0.1" size="0.001 0.2 0.1" rgba="0.615 0.71 0.576 1" solimp="0.99 0.99 0.01" contype="1" conaffinity="1" mass="100" solref="0.01 1"/>
            <geom name="back2" type="box" pos="-0.15 0 0.1" size="0.001 0.2 0.1" rgba="0.615 0.71 0.576 1" solimp="0.99 0.99 0.01" contype="1" conaffinity="1" mass="100" solref="0.01 1"/>
            <geom name="handle_21" type="capsule" fromto="0.15 -0.1 0.1 0.2 -0.05 0.1" size="0.01" rgba="1 1 1 1" solimp="0.99 0.99 0.01" contype="1" conaffinity="1" mass="100" solref="0.01 1"/>
            <geom name="handle_22" type="capsule" fromto="0.2 -0.05 0.1 0.2 0.05 0.1" size="0.01" rgba="1 1 1 1" solimp="0.99 0.99 0.01" contype="1" conaffinity="1" mass="100" solref="0.01 1"/>
            <geom name="handle_23" type="capsule" fromto="0.2 0.05 0.1 0.15 0.1 0.1" size="0.01" rgba="1 1 1 1" solimp="0.99 0.99 0.01" contype="1" conaffinity="1" mass="100" solref="0.01 1"/>
            <joint type="slide" pos="0 0 0" name="drawer2_joint" damping="0.5" axis="1 0 0" frictionloss="100" limited="false"/>
          </body>
         
          <body name="drawer3" pos="0 0 0.02">
            <geom name="bottom3" type="box" pos="0 0 0" size="0.15 0.2 0.001" rgba="0.615 0.71 0.576 1" solimp="0.99 0.99 0.01" contype="1" conaffinity="1" mass="100" solref="0.01 1"/>
            <geom name="left3" type="box" pos="0 -0.2 0.1" size="0.15 0.001 0.1" rgba="0.615 0.71 0.576 1" solimp="0.99 0.99 0.01" contype="1" conaffinity="1" mass="100" solref="0.01 1"/>
            <geom name="right3" type="box" pos="0 0.2 0.1" size="0.15 0.001 0.1" rgba="0.615 0.71 0.576 1" solimp="0.99 0.99 0.01" contype="1" conaffinity="1" mass="100" solref="0.01 1"/>
            <geom name="front3" type="box" pos="0.15 0 0.1" size="0.001 0.2 0.1" rgba="0.615 0.71 0.576 1" solimp="0.99 0.99 0.01" contype="1" conaffinity="1" mass="100" solref="0.01 1"/>
            <geom name="back3" type="box" pos="-0.15 0 0.1" size="0.001 0.2 0.1" rgba="0.615 0.71 0.576 1" solimp="0.99 0.99 0.01" contype="1" conaffinity="1" mass="100" solref="0.01 1"/>
            <geom name="handle_31" type="capsule" fromto="0.15 -0.1 0.1 0.2 -0.05 0.1" size="0.01" rgba="1 1 1 1" solimp="0.99 0.99 0.01" contype="1" conaffinity="1" mass="100" solref="0.01 1"/>
            <geom name="handle_32" type="capsule" fromto="0.2 -0.05 0.1 0.2 0.05 0.1" size="0.01" rgba="1 1 1 1" solimp="0.99 0.99 0.01" contype="1" conaffinity="1" mass="100" solref="0.01 1"/>
            <geom name="handle_33" type="capsule" fromto="0.2 0.05 0.1 0.15 0.1 0.1" size="0.01" rgba="1 1 1 1" solimp="0.99 0.99 0.01" contype="1" conaffinity="1" mass="100" solref="0.01 1"/>
            <joint type="slide" pos="0 0 0" name="drawer3_joint" damping="0.5" axis="1 0 0" frictionloss="10" limited="false"/>
          </body>

        </body>
        <light directional="true" ambient="0.2 0.2 0.2" diffuse="0 0 0" specular="0.01 0.01 0.01" castshadow="false" pos="4 0 4" dir="-1 0 -0.1" name="light0"></light>
		    <light directional="true" ambient="0.1 0.1 0.1" diffuse="0 0 0" specular="0.01 0.01 0.01" castshadow="false" pos="0 -4 4" dir="0 1 -0.1" name="light1"></light>
		    <light directional="true" ambient="0 0 0" diffuse="0 0 0" specular="0.01 0.01 0.01" castshadow="false" pos="40 4 4" name="light2"></light>
		    <light pos="1.3 0 2" castshadow="false" name="light3"></light>
		
		    <!-- <camera fovy="70" name="third_person" pos="2.5 0.3 1.5" euler="0 0.95 1.57"/>  -->
        <!-- <camera fovy="100" name="third_person" pos="1.9 0.65 1.5" quat="0 0 0.3826834 0.9238795"/> -->
        <camera fovy="75" name="third_person" pos="1.5 0.65 1.4" quat=" 0.2645862 0 0.3778281 0.8872655"/>
        
        <body name="camera_target" pos="1.50 0.2 0.8">
            <geom conaffinity="0" contype="0" pos="0 0 0" rgba="0 0 1 0" size="0.0475 0.0475 0.001" type="box"></geom>
        </body>

		<!-- <camera fovy="70" name="camera_dynamic" pos="1.1 0.6 1.0" euler="-1.0 -0.6 3.4"/> -->
    <!-- camera fovy="70" name="camera_dynamic" pos="1.15 0.6 1.0" mode="targetbody" target="camera_target"/> -->
    

    <!-- 2021/1/23 -->
    <camera fovy="70" name="camera_static" pos="1.6 0.8 1.0" euler="-1.4 0.4 3.05"/>
    <camera fovy="70" name="camera_dynamic" pos="1.3 0.8 1.1" euler="-1.4 0.2 3.05"/>
        

    </worldbody>

    <equality>
		<connect body2="left_finger" body1="left_inner_knuckle" anchor="0.0 0.035 0.042" solimp="0.9 0.95 0.001 0.5 2" solref="0.0002 1.0" ></connect>
		<connect body2="right_finger" body1="right_inner_knuckle" anchor="0.0 -0.035 0.042" solimp="0.9 0.95 0.001 0.5 2" solref="0.0002 1.0" ></connect>
		<joint joint1="left_inner_knuckle_joint" joint2="right_inner_knuckle_joint"></joint>
	</equality>
	<actuator>
		<motor ctrllimited="true" ctrlrange="-1.0 1.0" joint="left_inner_knuckle_joint" gear="200.0"/>
		<motor ctrllimited="true" ctrlrange="-1.0 1.0" joint="right_inner_knuckle_joint" gear="200.0"/>
	</actuator>

</mujoco>
<!-- [ 0.5235988, 0, 0.7853981 ] -->